[2024-06-19 13:19:33,834] {taskinstance.py:1179} INFO - Dependencies all met for <TaskInstance: tecnica_postgres.Insertar_Data manual__2024-06-19T13:13:26.281084+00:00 [queued]>
[2024-06-19 13:19:33,850] {taskinstance.py:1179} INFO - Dependencies all met for <TaskInstance: tecnica_postgres.Insertar_Data manual__2024-06-19T13:13:26.281084+00:00 [queued]>
[2024-06-19 13:19:33,851] {taskinstance.py:1376} INFO - 
--------------------------------------------------------------------------------
[2024-06-19 13:19:33,851] {taskinstance.py:1377} INFO - Starting attempt 2 of 2
[2024-06-19 13:19:33,852] {taskinstance.py:1378} INFO - 
--------------------------------------------------------------------------------
[2024-06-19 13:19:33,895] {taskinstance.py:1397} INFO - Executing <Task(PostgresFileOperator): Insertar_Data> on 2024-06-19 13:13:26.281084+00:00
[2024-06-19 13:19:33,900] {standard_task_runner.py:52} INFO - Started process 179 to run task
[2024-06-19 13:19:33,905] {standard_task_runner.py:79} INFO - Running: ['***', 'tasks', 'run', 'tecnica_postgres', 'Insertar_Data', 'manual__2024-06-19T13:13:26.281084+00:00', '--job-id', '27', '--raw', '--subdir', 'DAGS_FOLDER/tecnica_posgres.py', '--cfg-path', '/var/tmp/tmpjk9p0ibt', '--error-file', '/var/tmp/tmpyalbhbyw']
[2024-06-19 13:19:33,907] {standard_task_runner.py:80} INFO - Job 27: Subtask Insertar_Data
[2024-06-19 13:19:34,017] {task_command.py:371} INFO - Running <TaskInstance: tecnica_postgres.Insertar_Data manual__2024-06-19T13:13:26.281084+00:00 [running]> on host 284150aff6b6
[2024-06-19 13:19:34,145] {taskinstance.py:1591} INFO - Exporting the following env vars:
AIRFLOW_CTX_DAG_OWNER=***
AIRFLOW_CTX_DAG_ID=tecnica_postgres
AIRFLOW_CTX_TASK_ID=Insertar_Data
AIRFLOW_CTX_EXECUTION_DATE=2024-06-19T13:13:26.281084+00:00
AIRFLOW_CTX_TRY_NUMBER=2
AIRFLOW_CTX_DAG_RUN_ID=manual__2024-06-19T13:13:26.281084+00:00
[2024-06-19 13:19:34,146] {postgres.py:127} INFO - Running copy expert: COPY tecnica_ml FROM STDIN, filename: /opt/***/data/file.csv
[2024-06-19 13:19:34,175] {base.py:68} INFO - Using connection ID 'postgres_localhost' for task execution.
[2024-06-19 13:19:34,216] {taskinstance.py:1909} ERROR - Task failed with exception
Traceback (most recent call last):
  File "/opt/airflow/plugins/operators/PostgresFileOperator.py", line 22, in execute
    self.writeInDb()
  File "/opt/airflow/plugins/operators/PostgresFileOperator.py", line 27, in writeInDb
    self.postgres_hook.bulk_load(self.config.get("table_name"), "/opt/airflow/data/file.csv")
  File "/home/airflow/.local/lib/python3.7/site-packages/airflow/providers/postgres/hooks/postgres.py", line 149, in bulk_load
    self.copy_expert(f"COPY {table} FROM STDIN", tmp_file)
  File "/home/airflow/.local/lib/python3.7/site-packages/airflow/providers/postgres/hooks/postgres.py", line 135, in copy_expert
    cur.copy_expert(sql, file)
psycopg2.errors.UndefinedTable: relation "tecnica_ml" does not exist

[2024-06-19 13:19:34,248] {taskinstance.py:1420} INFO - Marking task as FAILED. dag_id=tecnica_postgres, task_id=Insertar_Data, execution_date=20240619T131326, start_date=20240619T131933, end_date=20240619T131934
[2024-06-19 13:19:34,592] {standard_task_runner.py:97} ERROR - Failed to execute job 27 for task Insertar_Data (relation "tecnica_ml" does not exist
; 179)
[2024-06-19 13:19:34,640] {local_task_job.py:156} INFO - Task exited with return code 1
[2024-06-19 13:19:34,706] {local_task_job.py:273} INFO - 0 downstream tasks scheduled from follow-on schedule check
