[2024-06-19 03:45:51,713] {taskinstance.py:1179} INFO - Dependencies all met for <TaskInstance: tecnica_postgres.Insertar_Data manual__2024-06-19T03:40:46.281041+00:00 [queued]>
[2024-06-19 03:45:51,725] {taskinstance.py:1179} INFO - Dependencies all met for <TaskInstance: tecnica_postgres.Insertar_Data manual__2024-06-19T03:40:46.281041+00:00 [queued]>
[2024-06-19 03:45:51,726] {taskinstance.py:1376} INFO - 
--------------------------------------------------------------------------------
[2024-06-19 03:45:51,726] {taskinstance.py:1377} INFO - Starting attempt 2 of 2
[2024-06-19 03:45:51,727] {taskinstance.py:1378} INFO - 
--------------------------------------------------------------------------------
[2024-06-19 03:45:51,746] {taskinstance.py:1397} INFO - Executing <Task(PostgresFileOperator): Insertar_Data> on 2024-06-19 03:40:46.281041+00:00
[2024-06-19 03:45:51,751] {standard_task_runner.py:52} INFO - Started process 3154 to run task
[2024-06-19 03:45:51,754] {standard_task_runner.py:79} INFO - Running: ['***', 'tasks', 'run', 'tecnica_postgres', 'Insertar_Data', 'manual__2024-06-19T03:40:46.281041+00:00', '--job-id', '7', '--raw', '--subdir', 'DAGS_FOLDER/tecnica_posgres.py', '--cfg-path', '/var/tmp/tmp9xrzxid6', '--error-file', '/var/tmp/tmpyb6ye2n1']
[2024-06-19 03:45:51,755] {standard_task_runner.py:80} INFO - Job 7: Subtask Insertar_Data
[2024-06-19 03:45:51,830] {task_command.py:371} INFO - Running <TaskInstance: tecnica_postgres.Insertar_Data manual__2024-06-19T03:40:46.281041+00:00 [running]> on host f8e18ce51c9d
[2024-06-19 03:45:51,929] {taskinstance.py:1591} INFO - Exporting the following env vars:
AIRFLOW_CTX_DAG_OWNER=***
AIRFLOW_CTX_DAG_ID=tecnica_postgres
AIRFLOW_CTX_TASK_ID=Insertar_Data
AIRFLOW_CTX_EXECUTION_DATE=2024-06-19T03:40:46.281041+00:00
AIRFLOW_CTX_TRY_NUMBER=2
AIRFLOW_CTX_DAG_RUN_ID=manual__2024-06-19T03:40:46.281041+00:00
[2024-06-19 03:45:51,929] {postgres.py:127} INFO - Running copy expert: COPY tecnica_ml FROM STDIN, filename: C:/Users/pc/Desktop/ETL_Mercado_libre/file.csv
[2024-06-19 03:45:51,930] {taskinstance.py:1909} ERROR - Task failed with exception
Traceback (most recent call last):
  File "/opt/airflow/plugins/operators/PostgresFileOperator.py", line 22, in execute
    self.writeInDb()
  File "/opt/airflow/plugins/operators/PostgresFileOperator.py", line 27, in writeInDb
    self.postgres_hook.bulk_load(self.config.get("table_name"), "C:/Users/pc/Desktop/ETL_Mercado_libre/file.csv")
  File "/home/airflow/.local/lib/python3.7/site-packages/airflow/providers/postgres/hooks/postgres.py", line 149, in bulk_load
    self.copy_expert(f"COPY {table} FROM STDIN", tmp_file)
  File "/home/airflow/.local/lib/python3.7/site-packages/airflow/providers/postgres/hooks/postgres.py", line 129, in copy_expert
    with open(filename, 'w'):
FileNotFoundError: [Errno 2] No such file or directory: 'C:/Users/pc/Desktop/ETL_Mercado_libre/file.csv'
[2024-06-19 03:45:51,953] {taskinstance.py:1420} INFO - Marking task as FAILED. dag_id=tecnica_postgres, task_id=Insertar_Data, execution_date=20240619T034046, start_date=20240619T034551, end_date=20240619T034551
[2024-06-19 03:45:51,968] {standard_task_runner.py:97} ERROR - Failed to execute job 7 for task Insertar_Data ([Errno 2] No such file or directory: 'C:/Users/pc/Desktop/ETL_Mercado_libre/file.csv'; 3154)
[2024-06-19 03:45:52,006] {local_task_job.py:156} INFO - Task exited with return code 1
[2024-06-19 03:45:52,047] {local_task_job.py:273} INFO - 0 downstream tasks scheduled from follow-on schedule check
